<?xml version="1.0" encoding="utf-8"?>
<!-- This URDF was automatically created by SolidWorks to URDF Exporter! Originally created by Stephen Brawner (brawner@gmail.com) 
     Commit Version: 1.6.0-4-g7f85cfe  Build Version: 1.6.7995.38578
     For more information, please see http://wiki.ros.org/sw_urdf_exporter -->
<robot
  name="assembly.SLDASM">
  <link
    name="base_link">
    <inertial>
      <origin
        xyz="-2.65978635290736E-18 2.32218677747017E-19 0.0359682827961964"
        rpy="0 0 0" />
      <mass
        value="0.349324168195258" />
      <inertia
        ixx="0.000303722827831119"
        ixy="-6.40012014226057E-21"
        ixz="-3.09225646669431E-20"
        iyy="0.000303722827831119"
        iyz="9.83403121094466E-21"
        izz="0.000269108517521699" />
    </inertial>
    <visual>
      <origin
        xyz="0 0 0"
        rpy="0 0 0" />
      <geometry>
        <mesh
          filename="../meshes/base_link.STL" />
      </geometry>
      <material
        name="">
        <color
          rgba="0.792156862745098 0.819607843137255 0.933333333333333 1" />
      </material>
    </visual>
    <collision>
      <origin
        xyz="0 0 0"
        rpy="0 0 0" />
      <geometry>
        <mesh
          filename="../meshes/base_link.STL" />
      </geometry>
    </collision>
  </link>
  <link
    name="link1">
    <inertial>
      <origin
        xyz="0.1 0.00499999999999999 8.0236264553021E-23"
        rpy="0 0 0" />
      <mass
        value="0.119242255003237" />
      <inertia
        ixx="2.48943667751497E-05"
        ixy="-2.10026327406034E-23"
        ixz="7.05860789378577E-22"
        iyy="0.00059439057933262"
        iyz="-8.82325986723232E-23"
        izz="0.000571483583474191" />
    </inertial>
    <visual>
      <origin
        xyz="0 0 0"
        rpy="0 0 0" />
      <geometry>
        <mesh
          filename="../meshes/link1.STL" />
      </geometry>
      <material
        name="">
        <color
          rgba="0.694117647058824 0.0980392156862745 0.0980392156862745 1" />
      </material>
    </visual>
    <collision>
      <origin
        xyz="0 0 0"
        rpy="0 0 0" />
      <geometry>
        <mesh
          filename="../meshes/link1.STL" />
      </geometry>
    </collision>
  </link>
  <joint
    name="joint1"
    type="revolute">
    <origin
      xyz="0 0 0.075"
      rpy="1.5708 0 0" />
    <parent
      link="base_link" />
    <child
      link="link1" />
    <axis
      xyz="0 1 0" />
    <limit
      lower="-1.5708"
      upper="1.5708"
      effort="0"
      velocity="0" />
  </joint>
  <link
    name="link2">
    <inertial>
      <origin
        xyz="0.1 -0.00499999999999998 -8.00757920239161E-20"
        rpy="0 0 0" />
      <mass
        value="0.119242255003237" />
      <inertia
        ixx="2.48943667751497E-05"
        ixy="-1.84112309778402E-21"
        ixz="-2.11758236813574E-21"
        iyy="0.00059439057933262"
        iyz="2.2940475654804E-22"
        izz="0.000571483583474191" />
    </inertial>
    <visual>
      <origin
        xyz="0 0 0"
        rpy="0 0 0" />
      <geometry>
        <mesh
          filename="../meshes/link2.STL" />
      </geometry>
      <material
        name="">
        <color
          rgba="0.792156862745098 0.819607843137255 0.933333333333333 1" />
      </material>
    </visual>
    <collision>
      <origin
        xyz="0 0 0"
        rpy="0 0 0" />
      <geometry>
        <mesh
          filename="../meshes/link2.STL" />
      </geometry>
    </collision>
  </link>
  <joint
    name="joint2"
    type="revolute">
    <origin
      xyz="0.2 0 0"
      rpy="0 0 0" />
    <parent
      link="link1" />
    <child
      link="link2" />
    <axis
      xyz="0 1 0" />
    <limit
      lower="-1.5708"
      upper="1.5708"
      effort="0"
      velocity="0" />
  </joint>
</robot>